Workbook
Name Accommodation_Based_Supported_Living_Providers_Current: Rates!$C$196:$C$259
Name After_Community_Network_Providers: Rates!$C$352:$C$386
Name After_Support: Lookup!$S$4:$S$7
Name After_Support_Description: Lookup!$S$3:$T$7
Name After_Supported_Living_Plus_With_Accomm_Providers: Rates!$C$306:$C$351
Name After_Supported_Living_Plus_Without_Accomm_Providers: Rates!$C$260:$C$305
Name After_Supported_Living_WITH_Accomm__Providers: Rates!$C$196:$C$259
Name After_Supported_Living_Without_Accomm_Providers: Rates!$C$132:$C$195
Name Current_CSE_Day_Care: Rates!$C$107:$C$131
Name Current_Outreach_Providers: Rates!$C$45:$C$69
Name Current_Support: Lookup!$Q$3:$Q$6
Name Current_Support_Description: Lookup!$Q$2:$R$6
Name Current_Supported_Living_Plus_Providers: Rates!$C$95:$C$106
Name Current_Supported_Living_Providers: Rates!$C$70:$C$94
Name Enhanced_Supported_Living_Providers_Current: Rates!$C$252:$C$293
Name ICB: Lookup!$AC$2:$AC$4
Name Legacy_Outreach_Providers: Rates!$C$3:$C$18
Name Legacy_Support: Lookup!$O$3:$O$5
Name Legacy_Support_Description: Lookup!$O$2:$P$5
Name Legacy_Supported_Living_Plus_Providers: Rates!$C$37:$C$44
Name Legacy_Supported_Living_Providers: Rates!$C$19:$C$36
Name NCCOnetoOneHours: 'CSE Calc'!$B$48
Name NoYes: Lookup!$G$3:$G$4
Name Outreach_Providers_Historic: Rates!$C$3:$C$18
Name Outreach_Providers_Legacy: Rates!$C$45:$C$69
Name Select_Provider: 'CSE Calc'!$B$30
Name SharedDaytimeContr: 'CSE Calc'!$B$58
Name SharedWakingNightsContr: 'CSE Calc'!$B$59
Name Standard_NonStandard: Lookup!$H$3:$H$4
Name SupportafterDec19: Lookup!$Q$3:$Q$6
Name SupportbeforeDec19: Lookup!$O$3:$O$5
Name Teams: Lookup!$I$3:$I$17
Name YesNo: Lookup!$F$3:$F$4

Sheet CSE Calc
A2: Care, Support and Enablement Calculator
A3: 6th April 2026 version of the Intranet CSE Calculator (vrs 1.0 updated 19/03/2026) | M3: Version of Calculator | N3: Locked
A5: Name of Social Work Community Team/NCC worker:
A7: Team:
A9: Name of the person receiving the service:
A11: Person's Mosaic ID:
A13: Other Details / Comments (If commissioning a temporary increase please ensure you state the end date for the increase)
M17: Figures used in Calculations or Final Description Text | O17: Figures used for Final Total Cost | Q17: Dropdowns / Lookup | T17: Check Data has been Entered Correctly | W17: Conditional Formatting / Activate Cell / Textbox
A20: Enter the date that the person first moved into the property and/or first received this service from this provider | I20: =IF(U20="Error","Error! Date of package change is before date package originally started!","") | Q20: Package Rates Range | R20: =IF(B20="","",(LOOKUP(B20,Lookup!K2:K4,Lookup!M2:M4))) | T20: Original Start Date Entered OK | U20: =IF(AND(B20>0,B22>0),IF(B22<B20,"Error","Y"),"N") -> N | W20: Activate: Date Message | X20: =B20>=Lookup!$K$4 -> FALSE
G21: =(IF(U22="Error",Lookup!$D$3,(IF(U24="Error",Lookup!$D$4,"")))) | Q21: Text in Package Start Textbox | R21: =IF(X20=TRUE,"This package will come under the new CSE Multi Provider framework.","")
A22: Effective Date or Date Package Changes | Q22: Dropdown - what type of support? | R22: =R20&"_Support" -> _Support | T22: Change Date Entered Check | U22: =IF(AND(B20>0,B22>0,U20="Y"),IF(B22<Lookup!$L$7,"Error","Y"),"N") -> N | W22: Activate: Effective Date or Date Package Changes | X22: =B20>0 -> FALSE
A24: Is this a Standard or Non-Standard Rate? | B24: Standard Rate | Q24: Dropdown - Standard / Non-Standard | R24: =IF(B22>0,"Standard_NonStandard","") | T24: Check Support Type is within Correct Date Range | U24: =IF(AND(B20>0,B22>0),(IF(AND(COUNTIF(INDIRECT(R22),B27)=0,B27<>""),"Error","Y")),0) -> 0 | W24: Activate: Standard/NonStandard | X24: =AND(X22=TRUE,B22>0) -> FALSE
Q26: Description Title | R26: =IF(AND(X28=TRUE,X29=TRUE),"Description of Package Type:","")
A27: What type of support is being provided? | M27: Accomm/Community | N27: =IF(B27<>"",IF(ISERROR((VLOOKUP(R29,Lookup!$V$3:$X$14,3,FALSE))),"",(VLOOKUP(R29,Lookup!$V$3:$X$14,3,FALSE))),"") | Q27: Text in Package Description Textbox | R27: =IF(X28=TRUE,R22&"_Description","") | T27: Support Type Entered? | U27: =IF(B27<>"","Y","N") -> N | W27: Activate: What type of support is being provided? | X27: =AND(((COUNTIF(U20:U24,"Y"))>=2),B24<>"") -> FALSE
Q28: Description Lookup | R28: =IF(AND(X28=TRUE,X29=TRUE),IF(ISERROR(VLOOKUP(B27,INDIRECT(R27),2,FALSE)),"",VLOOKUP(B27,INDIRECT(R27),2,FALSE)),"") | W28: Activate Description | X28: =AND(X27=TRUE,U27="Y") -> FALSE
Q29: Lookup - Determine if Service is Accomm-Based | R29: =R20&B27 | W29: Activate: Standard Provider? | X29: =AND(COUNTIF(U20:U27,"Y")>=4,B24="Standard Rate") -> FALSE
A30: Select Provider | H30: =IF(U30="Error","Error! Reselect the support type or the provider, or edit the original start date","") | M30: Provider for Summary | N30: =IF(B24="Standard Rate",B30,IF(B24="Non-Standard Rate",B32,"")) -> 0 | Q30: Lookup Range for Provider | R30: =IF(ISERROR(VLOOKUP((R20&B27),Lookup!$V$3:$W$14,2,FALSE)),"Error",(VLOOKUP((R20&B27),Lookup!$V$3:$W$14,2,FALSE))) -> Error | T30: Support Type and Provider within Correct Date Range | U30: =IF(B24="Standard Rate",(IF(Select_Provider="","",(IF((COUNTIF(U20:U27,"Y"))>=4,(IF((COUNTIF(Rates!$D$3:$D$386,R33))>0,"Y","Error")))))),"") | W30: Activate: Non-Standard Provider? | X30: =AND(X24=TRUE,B24="Non-Standard Rate",X78=FALSE) -> FALSE
T31: Provider Entered /Support Type Check | U31: =IF(B24="Standard Rate",(IF(COUNTIF($U$20:$U$30,"Y")>=4,(IF(B30<>"",(IF(R30="Error","Error","Y")),"Y")),"")),IF(B24="Non-Standard Rate",(IF(B32<>"","Y",""))))
A32: Enter Provider (Non-Standard) | T32: Basic details entered check (Standard Rate) | U32: =IF(B24="Standard Rate",(IF((COUNTIF(U20:U31,"Y"))=6,"Y","N")),"") -> N
A33: Hourly Rate to be applied: | B33: =IF(X34=TRUE,(INDEX(Rates!$F$3:$F$366,MATCH(R33,Rates!$D$3:$D$366,0))),0) -> 0 | J33: Cost per Week | Q33: Retrieve Hourly Rate | R33: =R20&B27&B30 | T33: Basic details entered check (Non - Standard Rate) | U33: =IF(B24="Non-Standard Rate",(IF((COUNTIF(U20:U27,"Y"))=4,"Y","N")),"")
A34: Enter Hourly Rate | M34: Hourly Rate | N34: =IF(X29=TRUE,B33,IF(X30=TRUE,B34,0)) -> 0 | W34: Activate Standard Hourly Rate | X34: =AND(COUNTIF($U$20:$U$31,"Y")>=6,B24="Standard Rate",B30<>"",X78=FALSE) -> FALSE
W35: Activate Non-Standard Hourly Rate | X35: =AND(COUNTIF($U$20:$U$31,"Y")>=5,B24="Non-Standard Rate",X78=FALSE) -> FALSE
A36: =IF(X38=TRUE,"Total Number of 1:1 Hours per Week:","") | H36: Total Cost of 1:1 Hours | J36: =IF(P36>0,P36,"") | O36: Total Cost of 1:1 hrs calc | P36: =IF(OR(U32="Y",U33="Y"),B36*N34,0) -> 0
G38: =IF(X39=TRUE,(VLOOKUP(B39,Lookup!$Z$2:$AA$3,2,FALSE)),"") | W38: Activate: Total Number of 1:1 Hours per Week: | X38: =AND(OR(X34=TRUE,X35=TRUE),N34>0) -> FALSE
A39: Health Funding: Does this Package receive funding from Health which the relevant ICB WILL PAY DIRECTLY TO THE PROVIDER? | Q39: Health Funding Dropdown | R39: =IF(X39=TRUE,"YesNo","") | W39: Activate question: Does this Package receive funding from Health? | X39: =AND(OR(U32="Y",U33="Y"),X38=TRUE) -> FALSE
W40: Activate: Health Funding Message | X40: =AND(N3="Locked",X39=TRUE) -> FALSE
A41: Which ICB will be paying DIRECTLY towards this package? | B41: North Notts (Bassetlaw) ICB | Q41: ICB Dropdown | R41: =IF(B39="Yes","ICB","") | W41: Activate Subsequent Calculations | X41: =IF(N3="Unlocked",IF((AND(OR(U32="Y",U33="Y"),X78=FALSE)),TRUE,FALSE),IF(N3="Locked",IF((AND(U32="Y",B39<>"Yes",X78=FALSE)),TRUE,FALSE))) -> FALSE
W42: Activate ICB Calculations | X42: =AND(N3="unlocked",B39="Yes") -> FALSE
A43: Number of 1:1 Hours to be paid by the ICB (Health) DIRECTLY to the provider: | G43: =IF(U43="error","Error! - More Health Funded Hours than Total 1:1 Hours","") | M43: ICB Funded Hours | N43: =IF(X43=TRUE,B43,0) -> 0 | T43: Health Hours Check | U43: =IF(AND(B36<>"",N43>B36,B39="Yes",U32="Y",X39=TRUE,X78=FALSE),"Error","") | W43: Activate: Which ICB and ICB Funded Hours? | X43: =AND(X41=TRUE,X39=TRUE,X42=TRUE,B39="Yes") -> FALSE
A45: =IF(X47=TRUE,"Total Cost of Contribution from "&CHAR(10)&B41&":","") | B45: =P45 -> 0 | G45: =IF(U45="error","Error! - Health contribution is more than the cost of 1:1 Hours","") | O45: Contribution from ICB | P45: =IF(X47=TRUE,N43*N34,0) -> 0 | T45: Health Contribution Check | U45: =IF(AND(B36<>"",B45>P36,B39="Yes",U32="Y",X47=TRUE,X78=FALSE),"Error","") | W45: Activate: Number of Hours 1:1 to be funded by Health: | X45: =AND(X43=TRUE,B41<>"") -> FALSE
W47: Activate: Total Cost of Contribution from ICB | X47: =AND(X45=TRUE,N43>0,U43<>"Error") -> FALSE
A48: Net Number of 1:1 Hours to be funded by NCC: | B48: =N48 -> 0 | G48: Net cost of 1:1 Hours to be funded by NCC | J48: =IF(X50=TRUE,P48,"") | M48: Net Hours funded by NCC Calc | N48: =IF(B36>0,B36-N43,0) -> 0 | O48: Net Cost of One to One Hours to NCC Calc | P48: =IF(X41=TRUE,P36-P45,"")
A50: Shared Hours - Total for this Service | W50: Activate:Net Number of 1:1 Hours / Net cost of 1:1 Hours to be funded by NCC | X50: =AND(X47=TRUE,U45<>"Error",X78=FALSE) -> FALSE
A51: Total No. of Shared Daytime Hours at the Service | H51: =IF(AND(X53=TRUE,G51<>""),(IF(G51<>1,"Hours","Hour")),"") | T51: Health Hrs and Contribution entered correctly | U51: =IF((COUNTIF(U43:U45,"Error")>0),"N","Y") -> Y
A52: Number of People Sharing Daytime Hours | H52: =IF(AND(X53=TRUE,G52>0),(IF(G52=1,"Person","People")),"")
A53: Total No. of Waking Night Hours at the Service | H53: =IF(AND(X53=TRUE,G53<>""),(IF(G53<>1,"Hours","Hour")),"") | I53: Waking Night Hours Label | W53: Activate: Total Shared Hours and Sleep-in cells | X53: =AND(OR($U$32="Y",U33="Y"),U51="Y",X41=TRUE,N27="Shared Hours") -> FALSE
A54: Number of People Sharing or Receiving Waking Night Hours | H54: =IF(AND(X53=TRUE,G54>0),(IF(G54=1,"Person","People")),"")
A57: Shared Hours Contributions:
A58: Individual Contribution to the Shared Daytime Hours | B58: =IF(X60=TRUE,ROUND(N58,2),"") | G58: Cost of Contribution to Shared Daytime Hours | J58: =IF(X60=TRUE,P58,"") | M58: Individual Contribution to the Shared Daytime Hours Calc | N58: =IF(X60=TRUE,ROUND((G51/G52),2),0) -> 0 | O58: Cost of Contribution to Shared Daytime Hours Calc | P58: =IF(X60=TRUE,ROUND((N58*$N$34),2),0) -> 0
A59: Individual Contribution to the Shared (or Single) Waking Night Hours | B59: =IF(X61=TRUE,ROUND(N59,2),"") | G59: Cost of Contribution to Shared (or Single) Waking Night Hours | J59: =IF(X61=TRUE,P59,"") | M59: Individual Contribution to the Shared (or Single) Waking Night Hours Calc | N59: =IF(X61=TRUE,ROUND((G53/G54),2),0) -> 0 | O59: Cost of Contribution to Shared Waking Night Hours Calc | P59: =IF(X61=TRUE,ROUND((N59*$N$34),2),0) -> 0
...

Sheet Description
B1: Date Person Moved in | C1: Date of Package Change | D1: Package Type Entered | E1: Provider Entered | G1: Activate Description
A2: Activate Description | B2: ='CSE Calc'!B20>0 -> FALSE | C2: ='CSE Calc'!B22>0 -> FALSE | D2: ='CSE Calc'!$N$27<>"" -> FALSE | E2: ='CSE Calc'!N30<>"" -> TRUE | G2: =IF(COUNTIF(B2:E2,TRUE)=4,"Y","N") -> N
A4: Specific Text Dependent on ICB Funding Yes/No:
A5: Text - 1:1 Daytime Support Hrs | B5: =IF('CSE Calc'!$B$39="Yes",'CSE Calc'!$N$48&" hrs of individual 1:1 daytime support per week to be funded by NCC",'CSE Calc'!$N$48&" hrs of individual 1:1 daytime support per week") -> 0 hrs of individual 1:1 daytime support per week
A6: Text - Total | B6: =IF('CSE Calc'!$B$39="Yes","Giving a Total Cost to NCC of","Giving a Total Cost of") -> Giving a Total Cost of
B8: Types of Support
A9: Package | B9: =IF('CSE Calc'!$B$27<>"",'CSE Calc'!$B$27,"")
A10: OnetoOneHours | B10: =IF(AND('CSE Calc'!$B$36>0,G2="Y"),A10,"")
A11: SharedDaytimeContr | B11: =IF(AND('CSE Calc'!$N$27="Shared Hours",'CSE Calc'!$N$58>0,G2="Y"),A11,"")
A12: SharedWakingNightsContr | B12: =IF(AND('CSE Calc'!$N$27="Shared Hours",'CSE Calc'!$N$59>0,G2="Y"),A12,"")
A13: SleepIn | B13: =IF(AND('CSE Calc'!N27="Shared Hours",'CSE Calc'!B63="Yes",'CSE Calc'!B67>0,G2="Y"),A13,"")
A14: Additional | B14: =IF(AND('CSE Calc'!B70>0,G2="Y"),A14,"")
B16: Package Details
A17: OnetoOneHours Details | B17: =IF(B10<>"",$B$5&" @ £"&TEXT('CSE Calc'!$N$34,"0.00")&" = £"&TEXT('CSE Calc'!$P$48,"0.00"),"")
A18: SharedDaytimeContr Details | B18: =IF(B11<>"",SharedDaytimeContr&" Hours of individual contribution to Shared Daytime Support per week @ £"&TEXT('CSE Calc'!$N$34,"0.00")&" per hour = £"&TEXT('CSE Calc'!$P$58,"0.00"),"")
A19: SharedWakingNightsContr Details | B19: =IF(B12<>"",'CSE Calc'!$N$59&" Hours of individual contribution to Shared Waking Nights Hours per week @ £"&TEXT('CSE Calc'!$N$34,"0.00")&" per hour = £"&TEXT('CSE Calc'!$P$59,"0.00"),"")
A20: SleepIn Details | B20: =IF(B13<>"",(IF('CSE Calc'!$B$67=1,"Single Person Sleep-In costs with "&'CSE Calc'!$N$66&" shifts per week = £"&TEXT('CSE Calc'!$P$67,"0.00"),"Individual contribution to Sleep-In costs per week with "&'CSE Calc'!$N$66&" shifts shared by "&'CSE Calc'!$N$65&" "&'CSE Calc'!$O$65&" = £"&TEXT('CSE Calc'!$P$67,"0.00"))),"")
A21: Additional Details | B21: =IF(B14<>"",("Additional Costs per week"&" = £"&TEXT('CSE Calc'!$B$70,"0.00")),"")
A22: Total Text | B22: =IF(AND('CSE Calc'!$P$73>0,G2="Y"),($B$6&" £"&TEXT('CSE Calc'!$P$73,"0.00")&" per week"),"")
A25: Actual Text in Description
A26: Cell | B26: Text in Cell
A27: CSE Calc Cell A80 | B27: {=IF(ISERROR(_xlfn._xlws.FILTER(B17:B22,(B17:B22<>""))),"",(_xlfn._xlws.FILTER(B17:B22,(B17:B22<>""))))}
A28: CSE Calc Cell A81
A29: CSE Calc Cell A82
A30: CSE Calc Cell A83
A31: CSE Calc Cell A84
A32: CSE Calc Cell A85
A34: Overridden Cost Narrative | B34: ="Overall support costing £"&'CSE Calc'!$J$75&" per week" -> Overall support costing £ per week

Sheet Rates
A1: New CSE Standard rates for Legacy, and Current packages for Outreach, Supported Living, Supported Living Plus and CSE Day Care 1:1 support from 6th of April 2026 and for New Providers under the 4th Sept 2025 framework with the new service descriptions of Supported Living, Supported Living with accommodation, Supported Living Plus, Supported Living Plus with accommodation and Community Networks. New current rates for shared daytime and shared waking night for Supported living and Supported living plus apply to Voids as well.(17th March 2026 version)
A2: Legacy before 10/04/2017 Current from 10/04/17 until 03/09/2025 After 04/09/2025 | B2: Support Type | C2: Provider | D2: Lookup Providers | E2: Current hourly rate from April 2025 | F2: New hourly rate from 6th April 2026 | G2: Lookup Type | H2: Sleep-In Cost per Night | I2: Sleep-in Cost per Week | J2: Comments/Rational for rate.
A3: Legacy | B3: Outreach | C3: Aspirations Care Ltd | D3: =A3&B3&C3 -> LegacyOutreachAspirations Care Ltd | E3: 23.3 | F3: 24 | G3: =A3&B3&C3&"Sleep-in" -> LegacyOutreachAspirations Care LtdSleep-in | H3: 0 | I3: 0 | J3: Historic Outreach capped at £23.30 | K3: Historic before 10/04/2017
A4: Legacy | B4: Outreach | C4: Blue Sky | D4: =A4&B4&C4 -> LegacyOutreachBlue Sky | E4: 23.8 | F4: 24 | G4: =A4&B4&C4&"Sleep-in" -> LegacyOutreachBlue SkySleep-in | H4: 0 | I4: 0 | J4: Historic Outreach higher rate frozen at £23.80 | K4: Historic before 10/04/2017
A5: Legacy | B5: Outreach | C5: Choice Support | D5: =A5&B5&C5 -> LegacyOutreachChoice Support | E5: 23.3 | F5: 24 | G5: =A5&B5&C5&"Sleep-in" -> LegacyOutreachChoice SupportSleep-in | H5: 0 | I5: 0 | J5: Historic Outreach capped at £23.30 | K5: Historic before 10/04/2017
A6: Legacy | B6: Outreach | C6: CIC | D6: =A6&B6&C6 -> LegacyOutreachCIC | E6: 23.8 | F6: 24 | G6: =A6&B6&C6&"Sleep-in" -> LegacyOutreachCICSleep-in | H6: 0 | I6: 0 | J6: Historic Outreach higher rate frozen at £23.80 | K6: Historic before 10/04/2017
A7: Legacy | B7: Outreach | C7: Eden Supported Living Ltd | D7: =A7&B7&C7 -> LegacyOutreachEden Supported Living Ltd | E7: 23.35 | F7: 24 | G7: =A7&B7&C7&"Sleep-in" -> LegacyOutreachEden Supported Living LtdSleep-in | H7: 0 | I7: 0 | J7: Historic Legacy Outreach rate frozen at £23.35 | K7: Historic before 10/04/2017
A8: Legacy | B8: Outreach | C8: Fitzroy | D8: =A8&B8&C8 -> LegacyOutreachFitzroy | E8: 23.8 | F8: 24 | G8: =A8&B8&C8&"Sleep-in" -> LegacyOutreachFitzroySleep-in | H8: 0 | I8: 0 | J8: Historic Outreach higher rate frozen at £23.80 | K8: Historic before 10/04/2017
A9: Legacy | B9: Outreach | C9: JRH Support (Nottingham) | D9: =A9&B9&C9 -> LegacyOutreachJRH Support (Nottingham) | E9: 23.3 | F9: 24 | G9: =A9&B9&C9&"Sleep-in" -> LegacyOutreachJRH Support (Nottingham)Sleep-in | H9: 0 | I9: 0 | J9: Historic Outreach capped at £23.30 | K9: Historic before 10/04/2017
A10: Legacy | B10: Outreach | C10: Lifeways | D10: =A10&B10&C10 -> LegacyOutreachLifeways | E10: 23.8 | F10: 24 | G10: =A10&B10&C10&"Sleep-in" -> LegacyOutreachLifewaysSleep-in | H10: 0 | I10: 0 | J10: Historic Outreach higher rate frozen at £23.80 | K10: Historic before 10/04/2017
A11: Legacy | B11: Outreach | C11: Mencap (Rushcliffe) - Royal Mencap Society | D11: =A11&B11&C11 -> LegacyOutreachMencap (Rushcliffe) - Royal Mencap Society | E11: 23.8 | F11: 24 | G11: =A11&B11&C11&"Sleep-in" -> LegacyOutreachMencap (Rushcliffe) - Royal Mencap SocietySleep-in | H11: 0 | I11: 0 | J11: Historic Outreach higher rate frozen at £23.80 | K11: Historic before 10/04/2017
A12: Legacy | B12: Outreach | C12: Mencap (Worksop) - Royal Mencap Society | D12: =A12&B12&C12 -> LegacyOutreachMencap (Worksop) - Royal Mencap Society | E12: 23.8 | F12: 24 | G12: =A12&B12&C12&"Sleep-in" -> LegacyOutreachMencap (Worksop) - Royal Mencap SocietySleep-in | H12: 0 | I12: 0 | J12: Historic Outreach higher rate frozen at £23.80 | K12: Historic before 10/04/2017
A13: Legacy | B13: Outreach | C13: Mencap Nottm- Gener8 | D13: =A13&B13&C13 -> LegacyOutreachMencap Nottm- Gener8 | E13: 23.8 | F13: 24 | G13: =A13&B13&C13&"Sleep-in" -> LegacyOutreachMencap Nottm- Gener8Sleep-in | H13: 0 | I13: 0 | J13: Historic Outreach higher rate frozen at £23.80 | K13: Historic before 10/04/2017
A14: Legacy | B14: Outreach | C14: NCHA | D14: =A14&B14&C14 -> LegacyOutreachNCHA | E14: 23.3 | F14: 24 | G14: =A14&B14&C14&"Sleep-in" -> LegacyOutreachNCHASleep-in | H14: 0 | I14: 0 | J14: Historic Outreach capped at £23.30 | K14: Historic before 10/04/2017
... A194: After | B194: Supported Living WITHOUT accommodation | C194: Voyage | D194: =A194&B194&C194 -> AfterSupported Living WITHOUT accommodationVoyage | E194: 23.3 | F194: 24 | G194: =A194&B194&C194&"Sleep-in" -> AfterSupported Living WITHOUT accommodationVoyageSleep-in | H194: 124.43 | I194: 871.01 | J194: Current Non accmmdtn based Supp Lvg (formerly Outreach & CSE Day Care 1:1) | K194: Current after 04/09/2025
A195: After | B195: Supported Living WITHOUT accommodation | C195: Warwickshire Living Ltd | D195: =A195&B195&C195 -> AfterSupported Living WITHOUT accommodationWarwickshire Living Ltd | E195: 23.3 | F195: 24 | G195: =A195&B195&C195&"Sleep-in" -> AfterSupported Living WITHOUT accommodationWarwickshire Living LtdSleep-in | H195: 124.43 | I195: 871.01 | J195: Current Non accmmdtn based Supp Lvg (formerly Outreach & CSE Day Care 1:1) | K195: Current after 04/09/2025 | P195: =SUM(I132:I195) -> 55647.95
A196: After | B196: Supported Living with accommodation | C196: Acclaim Care Agency Ltd | D196: =A196&B196&C196 -> AfterSupported Living with accommodationAcclaim Care Agency Ltd | E196: 23.3 | F196: 24 | G196: =A196&B196&C196&"Sleep-in" -> AfterSupported Living with accommodationAcclaim Care Agency LtdSleep-in | H196: 124.43 | I196: 871.01 | J196: Current Accommodation based supp lvng & Lot 3 | K196: Current after 04/09/2025
A197: After | B197: Supported Living with accommodation | C197: Achieve Together Ltd | D197: =A197&B197&C197 -> AfterSupported Living with accommodationAchieve Together Ltd | E197: 23.3 | F197: 24 | G197: =A197&B197&C197&"Sleep-in" -> AfterSupported Living with accommodationAchieve Together LtdSleep-in | H197: 124.43 | I197: 871.01 | J197: Current Accommodation based supp lvng & Lot 3 | K197: Current after 04/09/2025
A198: After | B198: Supported Living with accommodation | C198: All 4 Health Ltd | D198: =A198&B198&C198 -> AfterSupported Living with accommodationAll 4 Health Ltd | E198: 23.3 | F198: 24 | G198: =A198&B198&C198&"Sleep-in" -> AfterSupported Living with accommodationAll 4 Health LtdSleep-in | H198: 124.43 | I198: 871.01 | J198: Current Accommodation based supp lvng BUT NO Lot 3 | K198: Current after 04/09/2025
A199: After | B199: Supported Living with accommodation | C199: Alpha Health & Social Care Services Ltd | D199: =A199&B199&C199 -> AfterSupported Living with accommodationAlpha Health & Social Care Services Ltd | E199: 23.3 | F199: 24 | G199: =A199&B199&C199&"Sleep-in" -> AfterSupported Living with accommodationAlpha Health & Social Care Services LtdSleep-in | H199: 124.43 | I199: 871.01 | J199: Current Accommodation based supp lvng BUT NO Lot 3 | K199: Current after 04/09/2025
A200: After | B200: Supported Living with accommodation | C200: Ant and Bex Lodgings Ltd | D200: =A200&B200&C200 -> AfterSupported Living with accommodationAnt and Bex Lodgings Ltd | E200: 23.3 | F200: 24 | G200: =A200&B200&C200&"Sleep-in" -> AfterSupported Living with accommodationAnt and Bex Lodgings LtdSleep-in | H200: 124.43 | I200: 871.01 | J200: Current Accommodation based supp lvng BUT NO Lot 3 | K200: Current after 04/09/2025
A201: After | B201: Supported Living with accommodation | C201: AOC Homecare (t/a Angel Oak Care) | D201: =A201&B201&C201 -> AfterSupported Living with accommodationAOC Homecare (t/a Angel Oak Care) | E201: 23.3 | F201: 24 | G201: =A201&B201&C201&"Sleep-in" -> AfterSupported Living with accommodationAOC Homecare (t/a Angel Oak Care)Sleep-in | H201: 124.43 | I201: 871.01 | J201: Previously missed off CSE Calculator please insert now into this services | K201: Current after 04/09/2025
A202: After | B202: Supported Living with accommodation | C202: Archangel Enterprises Ltd | D202: =A202&B202&C202 -> AfterSupported Living with accommodationArchangel Enterprises Ltd | E202: 23.3 | F202: 24 | G202: =A202&B202&C202&"Sleep-in" -> AfterSupported Living with accommodationArchangel Enterprises LtdSleep-in | H202: 124.43 | I202: 871.01 | J202: Current Accommodation based supp lvng & Lot 3 | K202: Current after 04/09/2025
A203: After | B203: Supported Living with accommodation | C203: Aspirations Care Ltd | D203: =A203&B203&C203 -> AfterSupported Living with accommodationAspirations Care Ltd | E203: 23.3 | F203: 24 | G203: =A203&B203&C203&"Sleep-in" -> AfterSupported Living with accommodationAspirations Care LtdSleep-in | H203: 124.43 | I203: 871.01 | J203: Current Accommodation based supp lvng & Lot 3 | K203: Current after 04/09/2025
A204: After | B204: Supported Living with accommodation | C204: Autism East Midlands | D204: =A204&B204&C204 -> AfterSupported Living with accommodationAutism East Midlands | E204: 23.3 | F204: 24 | G204: =A204&B204&C204&"Sleep-in" -> AfterSupported Living with accommodationAutism East MidlandsSleep-in | H204: 124.43 | I204: 871.01 | J204: Current Accommodation based supp lvng BUT NO Lot 3 | K204: Current after 04/09/2025
A205: After | B205: Supported Living with accommodation | C205: Axis Recruitment Ltd | D205: =A205&B205&C205 -> AfterSupported Living with accommodationAxis Recruitment Ltd | E205: 23.3 | F205: 24 | G205: =A205&B205&C205&"Sleep-in" -> AfterSupported Living with accommodationAxis Recruitment LtdSleep-in | H205: 124.43 | I205: 871.01 | J205: Current Accommodation based supp lvng & Lot 3 | K205: Current after 04/09/2025
A206: After | B206: Supported Living with accommodation | C206: Break Barriers (Nottingham) Ltd | D206: =A206&B206&C206 -> AfterSupported Living with accommodationBreak Barriers (Nottingham) Ltd | E206: 23.3 | F206: 24 | G206: =A206&B206&C206&"Sleep-in" -> AfterSupported Living with accommodationBreak Barriers (Nottingham) LtdSleep-in | H206: 124.43 | I206: 871.01 | J206: Current Accommodation based supp lvng BUT NO Lot 3 | K206: Current after 04/09/2025
A207: After | B207: Supported Living with accommodation | C207: Care Sante London | D207: =A207&B207&C207 -> AfterSupported Living with accommodationCare Sante London | E207: 23.3 | F207: 24 | G207: =A207&B207&C207&"Sleep-in" -> AfterSupported Living with accommodationCare Sante LondonSleep-in | H207: 124.43 | I207: 871.01 | J207: Current Accommodation based supp lvng BUT NO Lot 3 | K207: Current after 04/09/2025
... A258: After | B258: Supported Living with accommodation | C258: Voyage | D258: =A258&B258&C258 -> AfterSupported Living with accommodationVoyage | E258: 23.3 | F258: 24 | G258: =A258&B258&C258&"Sleep-in" -> AfterSupported Living with accommodationVoyageSleep-in | H258: 124.43 | I258: 871.01 | J258: Current Accommodation based supp lvng & Lot 3 | K258: Current after 04/09/2025
A259: After | B259: Supported Living with accommodation | C259: Warwickshire Living Ltd | D259: =A259&B259&C259 -> AfterSupported Living with accommodationWarwickshire Living Ltd | E259: 23.3 | F259: 24 | G259: =A259&B259&C259&"Sleep-in" -> AfterSupported Living with accommodationWarwickshire Living LtdSleep-in | H259: 124.43 | I259: 871.01 | J259: Current Accommodation based supp lvng BUT NO Lot 3 | K259: Current after 04/09/2025 | O259: =SUM(I196:I259) -> 55647.95
A260: After | B260: Supported Living Plus without Accommodation | C260: Ace Care 4 U Ltd | D260: =A260&B260&C260 -> AfterSupported Living Plus without AccommodationAce Care 4 U Ltd | E260: 25.59 | F260: 26.36 | G260: =A260&B260&C260&"Sleep-in" -> AfterSupported Living Plus without AccommodationAce Care 4 U LtdSleep-in | H260: 124.43 | I260: 871.01 | J260: Current Supp Lvg Plus Provider Non Accommodation based support & Lot 3 | K260: Current after 04/09/2025
A261: After | B261: Supported Living Plus without Accommodation | C261: Achieve Together Ltd | D261: =A261&B261&C261 -> AfterSupported Living Plus without AccommodationAchieve Together Ltd | E261: 25.59 | F261: 26.36 | G261: =A261&B261&C261&"Sleep-in" -> AfterSupported Living Plus without AccommodationAchieve Together LtdSleep-in | H261: 124.43 | I261: 871.01 | J261: Current Supp Lvg Plus Provider Non Accommodation based support & Lot 3 | K261: Current after 04/09/2025
A262: After | B262: Supported Living Plus without Accommodation | C262: Alpha Health & Social Care Services Ltd | D262: =A262&B262&C262 -> AfterSupported Living Plus without AccommodationAlpha Health & Social Care Services Ltd | E262: 25.59 | F262: 26.36 | G262: =A262&B262&C262&"Sleep-in" -> AfterSupported Living Plus without AccommodationAlpha Health & Social Care Services LtdSleep-in | H262: 124.43 | I262: 871.01 | J262: Current Supp Lvg Plus provider NON accommodation based support BUT NO Lot 3 | K262: Current after 04/09/2025
A263: After | B263: Supported Living Plus without Accommodation | C263: AOC Homecare (t/a Angel Oak Care) | D263: =A263&B263&C263 -> AfterSupported Living Plus without AccommodationAOC Homecare (t/a Angel Oak Care) | E263: 25.59 | F263: 26.36 | G263: =A263&B263&C263&"Sleep-in" -> AfterSupported Living Plus without AccommodationAOC Homecare (t/a Angel Oak Care)Sleep-in | H263: 124.43 | I263: 871.01 | J263: Previously missed off CSE Calculator please insert now into this services | K263: Current after 04/09/2025
A264: After | B264: Supported Living Plus without Accommodation | C264: Archangel Enterprises Ltd | D264: =A264&B264&C264 -> AfterSupported Living Plus without AccommodationArchangel Enterprises Ltd | E264: 25.59 | F264: 26.36 | G264: =A264&B264&C264&"Sleep-in" -> AfterSupported Living Plus without AccommodationArchangel Enterprises LtdSleep-in | H264: 124.43 | I264: 871.01 | J264: Current Supp Lvg Plus Provider Non Accommodation based support & Lot 3 | K264: Current after 04/09/2025
A265: After | B265: Supported Living Plus without Accommodation | C265: Aspirations Care Ltd | D265: =A265&B265&C265 -> AfterSupported Living Plus without AccommodationAspirations Care Ltd | E265: 25.59 | F265: 26.36 | G265: =A265&B265&C265&"Sleep-in" -> AfterSupported Living Plus without AccommodationAspirations Care LtdSleep-in | H265: 124.43 | I265: 871.01 | J265: Current Supp Lvg Plus Provider Non Accommodation based support & Lot 3 | K265: Current after 04/09/2025
A266: After | B266: Supported Living Plus without Accommodation | C266: Autism East Midlands | D266: =A266&B266&C266 -> AfterSupported Living Plus without AccommodationAutism East Midlands | E266: 25.59 | F266: 26.36 | G266: =A266&B266&C266&"Sleep-in" -> AfterSupported Living Plus without AccommodationAutism East MidlandsSleep-in | H266: 124.43 | I266: 871.01 | J266: Current Supp Lvg Plus provider NON accommodation based support BUT NO Lot 3 | K266: Current after 04/09/2025
A267: After | B267: Supported Living Plus without Accommodation | C267: Axis Recruitment Ltd | D267: =A267&B267&C267 -> AfterSupported Living Plus without AccommodationAxis Recruitment Ltd | E267: 25.59 | F267: 26.36 | G267: =A267&B267&C267&"Sleep-in" -> AfterSupported Living Plus without AccommodationAxis Recruitment LtdSleep-in | H267: 124.43 | I267: 871.01 | J267: Current Supp Lvg Plus Provider Non Accommodation based support & Lot 3 | K267: Current after 04/09/2025
A268: After | B268: Supported Living Plus without Accommodation | C268: Bespoke Health & Social Care | D268: =A268&B268&C268 -> AfterSupported Living Plus without AccommodationBespoke Health & Social Care | E268: 25.59 | F268: 26.36 | G268: =A268&B268&C268&"Sleep-in" -> AfterSupported Living Plus without AccommodationBespoke Health & Social CareSleep-in | H268: 124.43 | I268: 871.01 | J268: Current Supp Lvg Plus Provider Non Accommodation based support & Lot 3 | K268: Current after 04/09/2025
A269: After | B269: Supported Living Plus without Accommodation | C269: Break Barriers (Nottingham) Ltd | D269: =A269&B269&C269 -> AfterSupported Living Plus without AccommodationBreak Barriers (Nottingham) Ltd | E269: 25.59 | F269: 26.36 | G269: =A269&B269&C269&"Sleep-in" -> AfterSupported Living Plus without AccommodationBreak Barriers (Nottingham) LtdSleep-in | H269: 124.43 | I269: 871.01 | J269: Current Supp Lvg Plus provider NON accommodation based support BUT NO Lot 3 | K269: Current after 04/09/2025
...

Sheet Lookup
K1: Package Rates Range | O1: Support Type | V1: Determine if Service is Accomm-Based | Z1: Health Funding Message | AC1: ICB
A2: Locked/ Unlocked | C2: Effective Date or Date Package Changes Error Messages | F2: YesNo | G2: NoYes | H2: Standard / Non-Standard | I2: Teams | K2: 1 | L2: 42834 | M2: Legacy | O2: Legacy | P2: Description | Q2: Current | R2: Description | S2: After 4th Sept 2025 | T2: Description | V2: Lookup Range for Provider | W2: Provider List | X2: Shared Hours / No Shared Hours | Z2: Yes | AA2: IF HEALTH ARE PAYING THEIR SHARE DIRECTLY TO THE PROVIDER – DO NOT complete this CSE calculator. Instead contact csesupport@nottscc.gov.uk and request a bespoke health funding direct to the CSE provider version of the CSE calculator | AC2: North Notts (Bassetlaw) ICB
A3: Locked | C3: Error-Change Date | D3: Date of package change is before the new rates were implemented from 7th April 2025. A different CSE Calculator is required. Contact csesupport@nottscc.gov.uk for the correct version to use | F3: Yes | G3: No | H3: Standard Rate | I3: Ashfield Social Work Community Team | K3: 42835 | L3: 45903 | M3: Current | O3: Outreach | P3: Supported package provided in the person’s own home or their carer’s and/or to facilitate access to the community that began BEFORE 10th April 2017 | Q3: Outreach | R3: Supported package provided in the person’s own home or their carer’s and/or to facilitate access to the community that began BETWEEN 10th April 2017 to 3rd September 2025. | S3: Community Network | V3: LegacyOutreach | W3: Legacy_Outreach_Providers | X3: No Shared Hours | Z3: No | AA3: Continue to complete this CSE calculator with NCC paying all the costs and complete an ACM33 to obtain Health’s contributions. | AC3: Mid Notts ICB
A4: Unlocked | C4: Error-Start Date | D4: Date when person moved in does NOT match the support type. Either change the date person moved in/began to receive service OR select a different support type | F4: No | G4: Yes | H4: Non-Standard Rate | I4: Bassetlaw Social Work Community Team | K4: 45904 | L4: 2958435 | M4: After | O4: Supported Living | P4: Accommodation based service that began BEFORE 10th April 2017 | Q4: CSE Day Care 1 to 1 support | R4: CSE daycare package that BETWEEN10th April 2017 to 3rd September 2025 | S4: Supported Living WITHOUT accommodation | T4: Formerly Outreach and CSE Day Care 1:1 support. NON ACCOMM based Supported Living, providing support in the person's OWN HOME or their carer's that OR 1:1 support delivered in a regulated DAY SERVICE or supervised formal setting that began ON or AFTER 4th Sept 2025. | V4: LegacySupported Living | W4: Legacy_Supported_Living_Providers | X4: Shared Hours | AC4: South Notts ICB
I5: Broxtowe Social Work Community Team | O5: Supported Living Plus | P5: Enhanced support that began BEFORE 10th April 2017 | Q5: Supported Living | R5: Accommodation based service that began BETWEEN 10th April 2017 to 3rd September 2025 | S5: Supported Living WITH accommodation | T5: ACCOMM based Supported Living. A package that provides support delivered in specially acquired supported living accommodation that began ON or AFTER 4th Sept 2025. | V5: LegacySupported Living Plus | W5: Legacy_Supported_Living_Plus_Providers | X5: Shared Hours
I6: Gedling Social Work Community Team | Q6: Supported Living Plus | R6: Enhanced support that began BETWEEN 10th April 2017 to 3rd September 2025 | S6: Supported Living Plus WITHOUT accommodation | T6: NON ACCOMM based Supported Living plus which has enhanced support that can be delivered in the person's OWN HOME or their carer's OR 1:1 support delivered in a regulated DAY SERVICE or supervised formal setting that began ON or AFTER 4th Sept 2025. | V6: CurrentOutreach | W6: Current_Outreach_Providers | X6: No Shared Hours
I7: Mansfield Social Work Community Team | K7: Date of Change for this CSE Calculator | L7: 45754 | S7: Supported Living Plus WITH accommodation | T7: ACCOMM based Supported Living for people with complex needs. A package that provides support delivered in specially acquired supported living accommodation that began ON or AFTER 4th Sept 2025. | V7: CurrentCSE Day Care 1 to 1 support | W7: Current_CSE_Day_Care | X7: No Shared Hours
I8: Newark & Shrwd Social Work Community Team | V8: CurrentSupported Living | W8: Current_Supported_Living_Providers | X8: Shared Hours
I9: Rushcliffe Social Work Community Team | V9: CurrentSupported Living Plus | W9: Current_Supported_Living_Plus_Providers | X9: Shared Hours
I10: Transforming Lives Team | V10: AfterCommunity Network | W10: After_Community_Network_Providers | X10: No Shared Hours
I11: Preparing for Adulthood Team | T11: =LEN(T6) -> 249 | V11: AfterSupported living WITHOUT accommodation | W11: After_Supported_Living_Without_Accomm_Providers | X11: Shared Hours | AC11: =V11=Z11 -> FALSE
I12: ADVIS | V12: AfterSupported Living WITH accommodation | W12: After_Supported_Living_WITH_Accomm__Providers | X12: Shared Hours
V13: AfterSupported Living Plus WITHOUT accommodation | W13: After_Supported_Living_Plus_Without_Accomm_Providers | X13: Shared Hours
V14: AfterSupported Living Plus WITH accommodation | W14: After_Supported_Living_Plus_With_Accomm_Providers | X14: Shared Hours
